no exception
I am inside finally block
test completed
